[2022-03-01 20:07:36,235] {taskinstance.py:1037} INFO - Dependencies all met for <TaskInstance: dag_flights.read_process_write_file manual__2022-03-01T20:06:39+00:00 [queued]>
[2022-03-01 20:07:36,448] {taskinstance.py:1037} INFO - Dependencies all met for <TaskInstance: dag_flights.read_process_write_file manual__2022-03-01T20:06:39+00:00 [queued]>
[2022-03-01 20:07:36,448] {taskinstance.py:1243} INFO - 
--------------------------------------------------------------------------------
[2022-03-01 20:07:36,448] {taskinstance.py:1244} INFO - Starting attempt 1 of 1
[2022-03-01 20:07:36,448] {taskinstance.py:1245} INFO - 
--------------------------------------------------------------------------------
[2022-03-01 20:07:36,707] {taskinstance.py:1264} INFO - Executing <Task(PythonOperator): read_process_write_file> on 2022-03-01 20:06:39+00:00
[2022-03-01 20:07:36,761] {standard_task_runner.py:52} INFO - Started process 4197 to run task
[2022-03-01 20:07:36,815] {standard_task_runner.py:76} INFO - Running: ['***', 'tasks', 'run', 'dag_flights', 'read_process_write_file', 'manual__2022-03-01T20:06:39+00:00', '--job-id', '52', '--raw', '--subdir', 'DAGS_FOLDER/dag_flights.py', '--cfg-path', '/tmp/tmpz9jq10e1', '--error-file', '/tmp/tmptdg0_vue']
[2022-03-01 20:07:36,816] {standard_task_runner.py:77} INFO - Job 52: Subtask read_process_write_file
[2022-03-01 20:07:37,886] {logging_mixin.py:109} INFO - Running <TaskInstance: dag_flights.read_process_write_file manual__2022-03-01T20:06:39+00:00 [running]> on host 083589a500f4
[2022-03-01 20:07:38,687] {warnings.py:110} WARNING - /home/***/.local/lib/python3.7/site-packages/***/models/xcom.py:437: SAWarning: TypeDecorator UtcDateTime(timezone=True) will not produce a cache key because the ``cache_ok`` attribute is not set to True.  This can have significant performance implications including some performance degradations in comparison to prior SQLAlchemy versions.  Set this attribute to True if this type object's state is safe to use in a cache key, or False to disable this warning. (Background on this error at: https://sqlalche.me/e/14/cprf)
  return query.delete()

[2022-03-01 20:07:38,879] {warnings.py:110} WARNING - /home/***/.local/lib/python3.7/site-packages/***/models/renderedtifields.py:126: SAWarning: TypeDecorator UtcDateTime(timezone=True) will not produce a cache key because the ``cache_ok`` attribute is not set to True.  This can have significant performance implications including some performance degradations in comparison to prior SQLAlchemy versions.  Set this attribute to True if this type object's state is safe to use in a cache key, or False to disable this warning. (Background on this error at: https://sqlalche.me/e/14/cprf)
  session.merge(self)

[2022-03-01 20:07:39,193] {warnings.py:110} WARNING - /home/***/.local/lib/python3.7/site-packages/***/models/renderedtifields.py:162: SAWarning: Coercing Subquery object into a select() for use in IN(); please pass a select() construct explicitly
  tuple_(cls.dag_id, cls.task_id, cls.execution_date).notin_(subq1),

[2022-03-01 20:07:39,371] {warnings.py:110} WARNING - /home/***/.local/lib/python3.7/site-packages/***/models/renderedtifields.py:163: SAWarning: TypeDecorator UtcDateTime(timezone=True) will not produce a cache key because the ``cache_ok`` attribute is not set to True.  This can have significant performance implications including some performance degradations in comparison to prior SQLAlchemy versions.  Set this attribute to True if this type object's state is safe to use in a cache key, or False to disable this warning. (Background on this error at: https://sqlalche.me/e/14/cprf)
  ).delete(synchronize_session=False)

[2022-03-01 20:07:39,587] {taskinstance.py:1431} INFO - Exporting the following env vars:
AIRFLOW_CTX_DAG_OWNER=***
AIRFLOW_CTX_DAG_ID=dag_flights
AIRFLOW_CTX_TASK_ID=read_process_write_file
AIRFLOW_CTX_EXECUTION_DATE=2022-03-01T20:06:39+00:00
AIRFLOW_CTX_DAG_RUN_ID=manual__2022-03-01T20:06:39+00:00
[2022-03-01 20:07:53,162] {__init__.py:490} WARNING - Matplotlib created a temporary config/cache directory at /tmp/matplotlib-n0o7efpw because the default path (/home/airflow/.cache/matplotlib) is not a writable directory; it is highly recommended to set the MPLCONFIGDIR environment variable to a writable directory, in particular to speed up the import of Matplotlib and to better support multiprocessing.
[2022-03-01 20:07:58,244] {font_manager.py:1061} WARNING - Matplotlib is building the font cache; this may take a moment.
[2022-03-01 20:08:00,409] {font_manager.py:1443} INFO - generated new fontManager
[2022-03-01 20:08:28,534] {logging_mixin.py:109} INFO - read success
[2022-03-01 20:08:28,535] {taskinstance.py:1718} ERROR - Task failed with exception
Traceback (most recent call last):
  File "/home/airflow/.local/lib/python3.7/site-packages/airflow/models/taskinstance.py", line 1334, in _run_raw_task
    self._execute_task_with_callbacks(context)
  File "/home/airflow/.local/lib/python3.7/site-packages/airflow/models/taskinstance.py", line 1460, in _execute_task_with_callbacks
    result = self._execute_task(context, self.task)
  File "/home/airflow/.local/lib/python3.7/site-packages/airflow/models/taskinstance.py", line 1516, in _execute_task
    result = execute_callable(context=context)
  File "/home/airflow/.local/lib/python3.7/site-packages/airflow/operators/python.py", line 174, in execute
    return_value = self.execute_callable()
  File "/home/airflow/.local/lib/python3.7/site-packages/airflow/operators/python.py", line 188, in execute_callable
    return self.python_callable(*self.op_args, **self.op_kwargs)
  File "/opt/airflow/dags/dag_flights.py", line 31, in read_process_write_file
    year_file = file_name.split('/')[-1]
NameError: name 'file_name' is not defined
[2022-03-01 20:08:28,875] {taskinstance.py:1282} INFO - Marking task as FAILED. dag_id=dag_flights, task_id=read_process_write_file, execution_date=20220301T200639, start_date=20220301T200736, end_date=20220301T200828
[2022-03-01 20:08:29,489] {standard_task_runner.py:92} ERROR - Failed to execute job 52 for task read_process_write_file
Traceback (most recent call last):
  File "/home/airflow/.local/lib/python3.7/site-packages/airflow/task/task_runner/standard_task_runner.py", line 85, in _start_by_fork
    args.func(args, dag=self.dag)
  File "/home/airflow/.local/lib/python3.7/site-packages/airflow/cli/cli_parser.py", line 48, in command
    return func(*args, **kwargs)
  File "/home/airflow/.local/lib/python3.7/site-packages/airflow/utils/cli.py", line 92, in wrapper
    return f(*args, **kwargs)
  File "/home/airflow/.local/lib/python3.7/site-packages/airflow/cli/commands/task_command.py", line 298, in task_run
    _run_task_by_selected_method(args, dag, ti)
  File "/home/airflow/.local/lib/python3.7/site-packages/airflow/cli/commands/task_command.py", line 107, in _run_task_by_selected_method
    _run_raw_task(args, ti)
  File "/home/airflow/.local/lib/python3.7/site-packages/airflow/cli/commands/task_command.py", line 184, in _run_raw_task
    error_file=args.error_file,
  File "/home/airflow/.local/lib/python3.7/site-packages/airflow/utils/session.py", line 70, in wrapper
    return func(*args, session=session, **kwargs)
  File "/home/airflow/.local/lib/python3.7/site-packages/airflow/models/taskinstance.py", line 1334, in _run_raw_task
    self._execute_task_with_callbacks(context)
  File "/home/airflow/.local/lib/python3.7/site-packages/airflow/models/taskinstance.py", line 1460, in _execute_task_with_callbacks
    result = self._execute_task(context, self.task)
  File "/home/airflow/.local/lib/python3.7/site-packages/airflow/models/taskinstance.py", line 1516, in _execute_task
    result = execute_callable(context=context)
  File "/home/airflow/.local/lib/python3.7/site-packages/airflow/operators/python.py", line 174, in execute
    return_value = self.execute_callable()
  File "/home/airflow/.local/lib/python3.7/site-packages/airflow/operators/python.py", line 188, in execute_callable
    return self.python_callable(*self.op_args, **self.op_kwargs)
  File "/opt/airflow/dags/dag_flights.py", line 31, in read_process_write_file
    year_file = file_name.split('/')[-1]
NameError: name 'file_name' is not defined
[2022-03-01 20:08:30,182] {local_task_job.py:154} INFO - Task exited with return code 1
[2022-03-01 20:08:30,426] {warnings.py:110} WARNING - /home/***/.local/lib/python3.7/site-packages/***/models/dag.py:1079: SADeprecationWarning: Query.value() is deprecated and will be removed in a future release.  Please use Query.with_entities() in combination with Query.scalar() (deprecated since: 1.4)
  return qry.value(DagModel.is_paused)

[2022-03-01 20:08:30,426] {warnings.py:110} WARNING - /home/***/.local/lib/python3.7/site-packages/***/models/dag.py:1079: SADeprecationWarning: Query.values() is deprecated and will be removed in a future release.  Please use Query.with_entities() (deprecated since: 1.4)
  return qry.value(DagModel.is_paused)

