[2022-03-01 14:36:55,458] {taskinstance.py:1037} INFO - Dependencies all met for <TaskInstance: dag_outliers2.read_process_write_file scheduled__2022-02-26T00:00:00+00:00 [queued]>
[2022-03-01 14:36:55,546] {taskinstance.py:1037} INFO - Dependencies all met for <TaskInstance: dag_outliers2.read_process_write_file scheduled__2022-02-26T00:00:00+00:00 [queued]>
[2022-03-01 14:36:55,546] {taskinstance.py:1243} INFO - 
--------------------------------------------------------------------------------
[2022-03-01 14:36:55,547] {taskinstance.py:1244} INFO - Starting attempt 1 of 1
[2022-03-01 14:36:55,547] {taskinstance.py:1245} INFO - 
--------------------------------------------------------------------------------
[2022-03-01 14:36:55,738] {taskinstance.py:1264} INFO - Executing <Task(PythonOperator): read_process_write_file> on 2022-02-26 00:00:00+00:00
[2022-03-01 14:36:55,790] {standard_task_runner.py:76} INFO - Running: ['***', 'tasks', 'run', 'dag_outliers2', 'read_process_write_file', 'scheduled__2022-02-26T00:00:00+00:00', '--job-id', '6', '--raw', '--subdir', 'DAGS_FOLDER/dag_outliers.py', '--cfg-path', '/tmp/tmp6huuols3', '--error-file', '/tmp/tmp0miucims']
[2022-03-01 14:36:55,801] {standard_task_runner.py:77} INFO - Job 6: Subtask read_process_write_file
[2022-03-01 14:36:55,783] {standard_task_runner.py:52} INFO - Started process 259 to run task
[2022-03-01 14:36:56,368] {warnings.py:110} WARNING - /home/***/.local/lib/python3.7/site-packages/***/models/dagrun.py:466: SAWarning: TypeDecorator UtcDateTime(timezone=True) will not produce a cache key because the ``cache_ok`` attribute is not set to True.  This can have significant performance implications including some performance degradations in comparison to prior SQLAlchemy versions.  Set this attribute to True if this type object's state is safe to use in a cache key, or False to disable this warning. (Background on this error at: https://sqlalche.me/e/14/cprf)
  return session.query(DagRun).filter(*filters).order_by(DagRun.execution_date.desc()).first()

[2022-03-01 14:36:56,407] {logging_mixin.py:109} INFO - Running <TaskInstance: dag_outliers2.read_process_write_file scheduled__2022-02-26T00:00:00+00:00 [running]> on host eff5a7a46f32
[2022-03-01 14:36:56,702] {warnings.py:110} WARNING - /home/***/.local/lib/python3.7/site-packages/***/models/dagrun.py:466: SAWarning: TypeDecorator UtcDateTime(timezone=True) will not produce a cache key because the ``cache_ok`` attribute is not set to True.  This can have significant performance implications including some performance degradations in comparison to prior SQLAlchemy versions.  Set this attribute to True if this type object's state is safe to use in a cache key, or False to disable this warning. (Background on this error at: https://sqlalche.me/e/14/cprf)
  return session.query(DagRun).filter(*filters).order_by(DagRun.execution_date.desc()).first()

[2022-03-01 14:36:56,722] {warnings.py:110} WARNING - /home/***/.local/lib/python3.7/site-packages/***/models/xcom.py:437: SAWarning: TypeDecorator UtcDateTime(timezone=True) will not produce a cache key because the ``cache_ok`` attribute is not set to True.  This can have significant performance implications including some performance degradations in comparison to prior SQLAlchemy versions.  Set this attribute to True if this type object's state is safe to use in a cache key, or False to disable this warning. (Background on this error at: https://sqlalche.me/e/14/cprf)
  return query.delete()

[2022-03-01 14:36:56,788] {warnings.py:110} WARNING - /home/***/.local/lib/python3.7/site-packages/***/models/renderedtifields.py:126: SAWarning: TypeDecorator UtcDateTime(timezone=True) will not produce a cache key because the ``cache_ok`` attribute is not set to True.  This can have significant performance implications including some performance degradations in comparison to prior SQLAlchemy versions.  Set this attribute to True if this type object's state is safe to use in a cache key, or False to disable this warning. (Background on this error at: https://sqlalche.me/e/14/cprf)
  session.merge(self)

[2022-03-01 14:36:56,824] {warnings.py:110} WARNING - /home/***/.local/lib/python3.7/site-packages/***/models/renderedtifields.py:162: SAWarning: Coercing Subquery object into a select() for use in IN(); please pass a select() construct explicitly
  tuple_(cls.dag_id, cls.task_id, cls.execution_date).notin_(subq1),

[2022-03-01 14:36:56,843] {warnings.py:110} WARNING - /home/***/.local/lib/python3.7/site-packages/***/models/renderedtifields.py:163: SAWarning: TypeDecorator UtcDateTime(timezone=True) will not produce a cache key because the ``cache_ok`` attribute is not set to True.  This can have significant performance implications including some performance degradations in comparison to prior SQLAlchemy versions.  Set this attribute to True if this type object's state is safe to use in a cache key, or False to disable this warning. (Background on this error at: https://sqlalche.me/e/14/cprf)
  ).delete(synchronize_session=False)

[2022-03-01 14:36:56,862] {taskinstance.py:1431} INFO - Exporting the following env vars:
AIRFLOW_CTX_DAG_OWNER=***
AIRFLOW_CTX_DAG_ID=dag_outliers2
AIRFLOW_CTX_TASK_ID=read_process_write_file
AIRFLOW_CTX_EXECUTION_DATE=2022-02-26T00:00:00+00:00
AIRFLOW_CTX_DAG_RUN_ID=scheduled__2022-02-26T00:00:00+00:00
[2022-03-01 14:36:58,475] {taskinstance.py:1718} ERROR - Task failed with exception
Traceback (most recent call last):
  File "/home/airflow/.local/lib/python3.7/site-packages/s3fs/core.py", line 282, in _call_s3
    out = await method(**additional_kwargs)
  File "/home/airflow/.local/lib/python3.7/site-packages/aiobotocore/client.py", line 225, in _make_api_call
    raise error_class(parsed_response, operation_name)
botocore.exceptions.ClientError: An error occurred (403) when calling the HeadObject operation: Forbidden

The above exception was the direct cause of the following exception:

Traceback (most recent call last):
  File "/home/airflow/.local/lib/python3.7/site-packages/airflow/models/taskinstance.py", line 1334, in _run_raw_task
    self._execute_task_with_callbacks(context)
  File "/home/airflow/.local/lib/python3.7/site-packages/airflow/models/taskinstance.py", line 1460, in _execute_task_with_callbacks
    result = self._execute_task(context, self.task)
  File "/home/airflow/.local/lib/python3.7/site-packages/airflow/models/taskinstance.py", line 1516, in _execute_task
    result = execute_callable(context=context)
  File "/home/airflow/.local/lib/python3.7/site-packages/airflow/operators/python.py", line 174, in execute
    return_value = self.execute_callable()
  File "/home/airflow/.local/lib/python3.7/site-packages/airflow/operators/python.py", line 188, in execute_callable
    return self.python_callable(*self.op_args, **self.op_kwargs)
  File "/opt/airflow/dags/dag_outliers.py", line 21, in read_process_write_file
    df1 = pd.read_csv('s3://airline-outliers/2009.csv')
  File "/home/airflow/.local/lib/python3.7/site-packages/pandas/util/_decorators.py", line 311, in wrapper
    return func(*args, **kwargs)
  File "/home/airflow/.local/lib/python3.7/site-packages/pandas/io/parsers/readers.py", line 586, in read_csv
    return _read(filepath_or_buffer, kwds)
  File "/home/airflow/.local/lib/python3.7/site-packages/pandas/io/parsers/readers.py", line 482, in _read
    parser = TextFileReader(filepath_or_buffer, **kwds)
  File "/home/airflow/.local/lib/python3.7/site-packages/pandas/io/parsers/readers.py", line 811, in __init__
    self._engine = self._make_engine(self.engine)
  File "/home/airflow/.local/lib/python3.7/site-packages/pandas/io/parsers/readers.py", line 1040, in _make_engine
    return mapping[engine](self.f, **self.options)  # type: ignore[call-arg]
  File "/home/airflow/.local/lib/python3.7/site-packages/pandas/io/parsers/c_parser_wrapper.py", line 51, in __init__
    self._open_handles(src, kwds)
  File "/home/airflow/.local/lib/python3.7/site-packages/pandas/io/parsers/base_parser.py", line 229, in _open_handles
    errors=kwds.get("encoding_errors", "strict"),
  File "/home/airflow/.local/lib/python3.7/site-packages/pandas/io/common.py", line 614, in get_handle
    storage_options=storage_options,
  File "/home/airflow/.local/lib/python3.7/site-packages/pandas/io/common.py", line 370, in _get_filepath_or_buffer
    filepath_or_buffer, mode=fsspec_mode, **(storage_options or {})
  File "/home/airflow/.local/lib/python3.7/site-packages/fsspec/core.py", line 140, in open
    out = self.__enter__()
  File "/home/airflow/.local/lib/python3.7/site-packages/fsspec/core.py", line 103, in __enter__
    f = self.fs.open(self.path, mode=mode)
  File "/home/airflow/.local/lib/python3.7/site-packages/fsspec/spec.py", line 1015, in open
    **kwargs,
  File "/home/airflow/.local/lib/python3.7/site-packages/s3fs/core.py", line 585, in _open
    cache_options=cache_options,
  File "/home/airflow/.local/lib/python3.7/site-packages/s3fs/core.py", line 1841, in __init__
    cache_options=cache_options,
  File "/home/airflow/.local/lib/python3.7/site-packages/fsspec/spec.py", line 1351, in __init__
    self.size = self.details["size"]
  File "/home/airflow/.local/lib/python3.7/site-packages/fsspec/spec.py", line 1364, in details
    self._details = self.fs.info(self.path)
  File "/home/airflow/.local/lib/python3.7/site-packages/fsspec/asyn.py", line 85, in wrapper
    return sync(self.loop, func, *args, **kwargs)
  File "/home/airflow/.local/lib/python3.7/site-packages/fsspec/asyn.py", line 65, in sync
    raise return_result
  File "/home/airflow/.local/lib/python3.7/site-packages/fsspec/asyn.py", line 25, in _runner
    result[0] = await coro
  File "/home/airflow/.local/lib/python3.7/site-packages/s3fs/core.py", line 1071, in _info
    **self.req_kw,
  File "/home/airflow/.local/lib/python3.7/site-packages/s3fs/core.py", line 302, in _call_s3
    raise err
PermissionError: Forbidden
[2022-03-01 14:36:58,493] {taskinstance.py:1282} INFO - Marking task as FAILED. dag_id=dag_outliers2, task_id=read_process_write_file, execution_date=20220226T000000, start_date=20220301T143655, end_date=20220301T143658
[2022-03-01 14:36:58,600] {standard_task_runner.py:92} ERROR - Failed to execute job 6 for task read_process_write_file
Traceback (most recent call last):
  File "/home/airflow/.local/lib/python3.7/site-packages/s3fs/core.py", line 282, in _call_s3
    out = await method(**additional_kwargs)
  File "/home/airflow/.local/lib/python3.7/site-packages/aiobotocore/client.py", line 225, in _make_api_call
    raise error_class(parsed_response, operation_name)
botocore.exceptions.ClientError: An error occurred (403) when calling the HeadObject operation: Forbidden

The above exception was the direct cause of the following exception:

Traceback (most recent call last):
  File "/home/airflow/.local/lib/python3.7/site-packages/airflow/task/task_runner/standard_task_runner.py", line 85, in _start_by_fork
    args.func(args, dag=self.dag)
  File "/home/airflow/.local/lib/python3.7/site-packages/airflow/cli/cli_parser.py", line 48, in command
    return func(*args, **kwargs)
  File "/home/airflow/.local/lib/python3.7/site-packages/airflow/utils/cli.py", line 92, in wrapper
    return f(*args, **kwargs)
  File "/home/airflow/.local/lib/python3.7/site-packages/airflow/cli/commands/task_command.py", line 298, in task_run
    _run_task_by_selected_method(args, dag, ti)
  File "/home/airflow/.local/lib/python3.7/site-packages/airflow/cli/commands/task_command.py", line 107, in _run_task_by_selected_method
    _run_raw_task(args, ti)
  File "/home/airflow/.local/lib/python3.7/site-packages/airflow/cli/commands/task_command.py", line 184, in _run_raw_task
    error_file=args.error_file,
  File "/home/airflow/.local/lib/python3.7/site-packages/airflow/utils/session.py", line 70, in wrapper
    return func(*args, session=session, **kwargs)
  File "/home/airflow/.local/lib/python3.7/site-packages/airflow/models/taskinstance.py", line 1334, in _run_raw_task
    self._execute_task_with_callbacks(context)
  File "/home/airflow/.local/lib/python3.7/site-packages/airflow/models/taskinstance.py", line 1460, in _execute_task_with_callbacks
    result = self._execute_task(context, self.task)
  File "/home/airflow/.local/lib/python3.7/site-packages/airflow/models/taskinstance.py", line 1516, in _execute_task
    result = execute_callable(context=context)
  File "/home/airflow/.local/lib/python3.7/site-packages/airflow/operators/python.py", line 174, in execute
    return_value = self.execute_callable()
  File "/home/airflow/.local/lib/python3.7/site-packages/airflow/operators/python.py", line 188, in execute_callable
    return self.python_callable(*self.op_args, **self.op_kwargs)
  File "/opt/airflow/dags/dag_outliers.py", line 21, in read_process_write_file
    df1 = pd.read_csv('s3://airline-outliers/2009.csv')
  File "/home/airflow/.local/lib/python3.7/site-packages/pandas/util/_decorators.py", line 311, in wrapper
    return func(*args, **kwargs)
  File "/home/airflow/.local/lib/python3.7/site-packages/pandas/io/parsers/readers.py", line 586, in read_csv
    return _read(filepath_or_buffer, kwds)
  File "/home/airflow/.local/lib/python3.7/site-packages/pandas/io/parsers/readers.py", line 482, in _read
    parser = TextFileReader(filepath_or_buffer, **kwds)
  File "/home/airflow/.local/lib/python3.7/site-packages/pandas/io/parsers/readers.py", line 811, in __init__
    self._engine = self._make_engine(self.engine)
  File "/home/airflow/.local/lib/python3.7/site-packages/pandas/io/parsers/readers.py", line 1040, in _make_engine
    return mapping[engine](self.f, **self.options)  # type: ignore[call-arg]
  File "/home/airflow/.local/lib/python3.7/site-packages/pandas/io/parsers/c_parser_wrapper.py", line 51, in __init__
    self._open_handles(src, kwds)
  File "/home/airflow/.local/lib/python3.7/site-packages/pandas/io/parsers/base_parser.py", line 229, in _open_handles
    errors=kwds.get("encoding_errors", "strict"),
  File "/home/airflow/.local/lib/python3.7/site-packages/pandas/io/common.py", line 614, in get_handle
    storage_options=storage_options,
  File "/home/airflow/.local/lib/python3.7/site-packages/pandas/io/common.py", line 370, in _get_filepath_or_buffer
    filepath_or_buffer, mode=fsspec_mode, **(storage_options or {})
  File "/home/airflow/.local/lib/python3.7/site-packages/fsspec/core.py", line 140, in open
    out = self.__enter__()
  File "/home/airflow/.local/lib/python3.7/site-packages/fsspec/core.py", line 103, in __enter__
    f = self.fs.open(self.path, mode=mode)
  File "/home/airflow/.local/lib/python3.7/site-packages/fsspec/spec.py", line 1015, in open
    **kwargs,
  File "/home/airflow/.local/lib/python3.7/site-packages/s3fs/core.py", line 585, in _open
    cache_options=cache_options,
  File "/home/airflow/.local/lib/python3.7/site-packages/s3fs/core.py", line 1841, in __init__
    cache_options=cache_options,
  File "/home/airflow/.local/lib/python3.7/site-packages/fsspec/spec.py", line 1351, in __init__
    self.size = self.details["size"]
  File "/home/airflow/.local/lib/python3.7/site-packages/fsspec/spec.py", line 1364, in details
    self._details = self.fs.info(self.path)
  File "/home/airflow/.local/lib/python3.7/site-packages/fsspec/asyn.py", line 85, in wrapper
    return sync(self.loop, func, *args, **kwargs)
  File "/home/airflow/.local/lib/python3.7/site-packages/fsspec/asyn.py", line 65, in sync
    raise return_result
  File "/home/airflow/.local/lib/python3.7/site-packages/fsspec/asyn.py", line 25, in _runner
    result[0] = await coro
  File "/home/airflow/.local/lib/python3.7/site-packages/s3fs/core.py", line 1071, in _info
    **self.req_kw,
  File "/home/airflow/.local/lib/python3.7/site-packages/s3fs/core.py", line 302, in _call_s3
    raise err
PermissionError: Forbidden
[2022-03-01 14:36:58,707] {local_task_job.py:154} INFO - Task exited with return code 1
[2022-03-01 14:36:58,767] {local_task_job.py:264} INFO - 0 downstream tasks scheduled from follow-on schedule check
[2022-03-01 14:36:58,768] {warnings.py:110} WARNING - /home/***/.local/lib/python3.7/site-packages/***/models/dag.py:1079: SADeprecationWarning: Query.value() is deprecated and will be removed in a future release.  Please use Query.with_entities() in combination with Query.scalar() (deprecated since: 1.4)
  return qry.value(DagModel.is_paused)

[2022-03-01 14:36:58,769] {warnings.py:110} WARNING - /home/***/.local/lib/python3.7/site-packages/***/models/dag.py:1079: SADeprecationWarning: Query.values() is deprecated and will be removed in a future release.  Please use Query.with_entities() (deprecated since: 1.4)
  return qry.value(DagModel.is_paused)

