[2022-03-01 19:36:27,177] {taskinstance.py:1037} INFO - Dependencies all met for <TaskInstance: dag_outliers2.read_process_write_file manual__2022-03-01T19:36:20.786798+00:00 [queued]>
[2022-03-01 19:36:27,210] {taskinstance.py:1037} INFO - Dependencies all met for <TaskInstance: dag_outliers2.read_process_write_file manual__2022-03-01T19:36:20.786798+00:00 [queued]>
[2022-03-01 19:36:27,210] {taskinstance.py:1243} INFO - 
--------------------------------------------------------------------------------
[2022-03-01 19:36:27,210] {taskinstance.py:1244} INFO - Starting attempt 1 of 1
[2022-03-01 19:36:27,211] {taskinstance.py:1245} INFO - 
--------------------------------------------------------------------------------
[2022-03-01 19:36:27,240] {taskinstance.py:1264} INFO - Executing <Task(PythonOperator): read_process_write_file> on 2022-03-01 19:36:20.786798+00:00
[2022-03-01 19:36:27,247] {standard_task_runner.py:52} INFO - Started process 3152 to run task
[2022-03-01 19:36:27,257] {standard_task_runner.py:76} INFO - Running: ['***', 'tasks', 'run', 'dag_outliers2', 'read_process_write_file', 'manual__2022-03-01T19:36:20.786798+00:00', '--job-id', '48', '--raw', '--subdir', 'DAGS_FOLDER/dag_outliers.py', '--cfg-path', '/tmp/tmpm34vpe5a', '--error-file', '/tmp/tmpozgwjdgf']
[2022-03-01 19:36:27,259] {standard_task_runner.py:77} INFO - Job 48: Subtask read_process_write_file
[2022-03-01 19:36:27,360] {logging_mixin.py:109} INFO - Running <TaskInstance: dag_outliers2.read_process_write_file manual__2022-03-01T19:36:20.786798+00:00 [running]> on host 083589a500f4
[2022-03-01 19:36:27,503] {warnings.py:110} WARNING - /home/***/.local/lib/python3.7/site-packages/***/models/xcom.py:437: SAWarning: TypeDecorator UtcDateTime(timezone=True) will not produce a cache key because the ``cache_ok`` attribute is not set to True.  This can have significant performance implications including some performance degradations in comparison to prior SQLAlchemy versions.  Set this attribute to True if this type object's state is safe to use in a cache key, or False to disable this warning. (Background on this error at: https://sqlalche.me/e/14/cprf)
  return query.delete()

[2022-03-01 19:36:27,525] {warnings.py:110} WARNING - /home/***/.local/lib/python3.7/site-packages/***/models/renderedtifields.py:126: SAWarning: TypeDecorator UtcDateTime(timezone=True) will not produce a cache key because the ``cache_ok`` attribute is not set to True.  This can have significant performance implications including some performance degradations in comparison to prior SQLAlchemy versions.  Set this attribute to True if this type object's state is safe to use in a cache key, or False to disable this warning. (Background on this error at: https://sqlalche.me/e/14/cprf)
  session.merge(self)

[2022-03-01 19:36:27,541] {warnings.py:110} WARNING - /home/***/.local/lib/python3.7/site-packages/***/models/renderedtifields.py:162: SAWarning: Coercing Subquery object into a select() for use in IN(); please pass a select() construct explicitly
  tuple_(cls.dag_id, cls.task_id, cls.execution_date).notin_(subq1),

[2022-03-01 19:36:27,554] {warnings.py:110} WARNING - /home/***/.local/lib/python3.7/site-packages/***/models/renderedtifields.py:163: SAWarning: TypeDecorator UtcDateTime(timezone=True) will not produce a cache key because the ``cache_ok`` attribute is not set to True.  This can have significant performance implications including some performance degradations in comparison to prior SQLAlchemy versions.  Set this attribute to True if this type object's state is safe to use in a cache key, or False to disable this warning. (Background on this error at: https://sqlalche.me/e/14/cprf)
  ).delete(synchronize_session=False)

[2022-03-01 19:36:27,561] {taskinstance.py:1431} INFO - Exporting the following env vars:
AIRFLOW_CTX_DAG_OWNER=***
AIRFLOW_CTX_DAG_ID=dag_outliers2
AIRFLOW_CTX_TASK_ID=read_process_write_file
AIRFLOW_CTX_EXECUTION_DATE=2022-03-01T19:36:20.786798+00:00
AIRFLOW_CTX_DAG_RUN_ID=manual__2022-03-01T19:36:20.786798+00:00
[2022-03-01 19:36:29,064] {logging_mixin.py:109} INFO - read success
[2022-03-01 19:36:29,207] {taskinstance.py:1718} ERROR - Task failed with exception
Traceback (most recent call last):
  File "/home/airflow/.local/lib/python3.7/site-packages/sqlalchemy/engine/base.py", line 1783, in _execute_context
    cursor, statement, parameters, context
  File "/home/airflow/.local/lib/python3.7/site-packages/sqlalchemy/dialects/postgresql/psycopg2.py", line 957, in do_executemany
    **kwargs
  File "/home/airflow/.local/lib/python3.7/site-packages/psycopg2/extras.py", line 1270, in execute_values
    cur.execute(b''.join(parts))
psycopg2.errors.UndefinedTable: relation "flights" does not exist
LINE 1: INSERT INTO flights ("FL_DATE", "ORIGIN", "DEP_DELAY", pred,...
                    ^


The above exception was the direct cause of the following exception:

Traceback (most recent call last):
  File "/home/airflow/.local/lib/python3.7/site-packages/airflow/models/taskinstance.py", line 1334, in _run_raw_task
    self._execute_task_with_callbacks(context)
  File "/home/airflow/.local/lib/python3.7/site-packages/airflow/models/taskinstance.py", line 1460, in _execute_task_with_callbacks
    result = self._execute_task(context, self.task)
  File "/home/airflow/.local/lib/python3.7/site-packages/airflow/models/taskinstance.py", line 1516, in _execute_task
    result = execute_callable(context=context)
  File "/home/airflow/.local/lib/python3.7/site-packages/airflow/operators/python.py", line 174, in execute
    return_value = self.execute_callable()
  File "/home/airflow/.local/lib/python3.7/site-packages/airflow/operators/python.py", line 188, in execute_callable
    return self.python_callable(*self.op_args, **self.op_kwargs)
  File "/opt/airflow/dags/dag_outliers.py", line 46, in read_process_write_file
    df1.to_sql(con=database_connection, name='flights', if_exists='replace',index=False)
  File "/home/airflow/.local/lib/python3.7/site-packages/pandas/core/generic.py", line 2882, in to_sql
    method=method,
  File "/home/airflow/.local/lib/python3.7/site-packages/pandas/io/sql.py", line 728, in to_sql
    **engine_kwargs,
  File "/home/airflow/.local/lib/python3.7/site-packages/pandas/io/sql.py", line 1770, in to_sql
    **engine_kwargs,
  File "/home/airflow/.local/lib/python3.7/site-packages/pandas/io/sql.py", line 1350, in insert_records
    raise err
  File "/home/airflow/.local/lib/python3.7/site-packages/pandas/io/sql.py", line 1340, in insert_records
    table.insert(chunksize=chunksize, method=method)
  File "/home/airflow/.local/lib/python3.7/site-packages/pandas/io/sql.py", line 967, in insert
    exec_insert(conn, keys, chunk_iter)
  File "/home/airflow/.local/lib/python3.7/site-packages/pandas/io/sql.py", line 882, in _execute_insert
    conn.execute(self.table.insert(), data)
  File "/home/airflow/.local/lib/python3.7/site-packages/sqlalchemy/engine/base.py", line 1289, in execute
    return meth(self, multiparams, params, _EMPTY_EXECUTION_OPTS)
  File "/home/airflow/.local/lib/python3.7/site-packages/sqlalchemy/sql/elements.py", line 326, in _execute_on_connection
    self, multiparams, params, execution_options
  File "/home/airflow/.local/lib/python3.7/site-packages/sqlalchemy/engine/base.py", line 1491, in _execute_clauseelement
    cache_hit=cache_hit,
  File "/home/airflow/.local/lib/python3.7/site-packages/sqlalchemy/engine/base.py", line 1846, in _execute_context
    e, statement, parameters, cursor, context
  File "/home/airflow/.local/lib/python3.7/site-packages/sqlalchemy/engine/base.py", line 2027, in _handle_dbapi_exception
    sqlalchemy_exception, with_traceback=exc_info[2], from_=e
  File "/home/airflow/.local/lib/python3.7/site-packages/sqlalchemy/util/compat.py", line 207, in raise_
    raise exception
  File "/home/airflow/.local/lib/python3.7/site-packages/sqlalchemy/engine/base.py", line 1783, in _execute_context
    cursor, statement, parameters, context
  File "/home/airflow/.local/lib/python3.7/site-packages/sqlalchemy/dialects/postgresql/psycopg2.py", line 957, in do_executemany
    **kwargs
  File "/home/airflow/.local/lib/python3.7/site-packages/psycopg2/extras.py", line 1270, in execute_values
    cur.execute(b''.join(parts))
sqlalchemy.exc.ProgrammingError: (psycopg2.errors.UndefinedTable) relation "flights" does not exist
LINE 1: INSERT INTO flights ("FL_DATE", "ORIGIN", "DEP_DELAY", pred,...
                    ^

[SQL: INSERT INTO flights ("FL_DATE", "ORIGIN", "DEP_DELAY", pred, result) VALUES (%(FL_DATE)s, %(ORIGIN)s, %(DEP_DELAY)s, %(pred)s, %(result)s)]
[parameters: ({'FL_DATE': '2009-01-01', 'ORIGIN': 'ABQ', 'DEP_DELAY': -8.0, 'pred': 0, 'result': 'normal'}, {'FL_DATE': '2009-01-01', 'ORIGIN': 'IAD', 'DEP_DELAY': -10.0, 'pred': 0, 'result': 'normal'}, {'FL_DATE': '2009-01-01', 'ORIGIN': 'IAH', 'DEP_DELAY': -0.23076923076923078, 'pred': 0, 'result': 'normal'}, {'FL_DATE': '2009-01-01', 'ORIGIN': 'IND', 'DEP_DELAY': -2.5, 'pred': 0, 'result': 'normal'}, {'FL_DATE': '2009-01-01', 'ORIGIN': 'JAN', 'DEP_DELAY': 3.0, 'pred': 1, 'result': 'outlier'}, {'FL_DATE': '2009-01-01', 'ORIGIN': 'JAX', 'DEP_DELAY': -9.0, 'pred': 0, 'result': 'normal'}, {'FL_DATE': '2009-01-01', 'ORIGIN': 'LFT', 'DEP_DELAY': -7.0, 'pred': 0, 'result': 'normal'}, {'FL_DATE': '2009-01-01', 'ORIGIN': 'GSO', 'DEP_DELAY': -1.0, 'pred': 0, 'result': 'normal'}  ... displaying 10 of 36 total bound parameter sets ...  {'FL_DATE': '2009-01-01', 'ORIGIN': 'RSW', 'DEP_DELAY': -9.0, 'pred': 0, 'result': 'normal'}, {'FL_DATE': '2009-01-01', 'ORIGIN': 'TYS', 'DEP_DELAY': -5.0, 'pred': 0, 'result': 'normal'})]
(Background on this error at: https://sqlalche.me/e/14/f405)
[2022-03-01 19:36:29,258] {taskinstance.py:1282} INFO - Marking task as FAILED. dag_id=dag_outliers2, task_id=read_process_write_file, execution_date=20220301T193620, start_date=20220301T193627, end_date=20220301T193629
[2022-03-01 19:36:29,273] {standard_task_runner.py:92} ERROR - Failed to execute job 48 for task read_process_write_file
Traceback (most recent call last):
  File "/home/airflow/.local/lib/python3.7/site-packages/sqlalchemy/engine/base.py", line 1783, in _execute_context
    cursor, statement, parameters, context
  File "/home/airflow/.local/lib/python3.7/site-packages/sqlalchemy/dialects/postgresql/psycopg2.py", line 957, in do_executemany
    **kwargs
  File "/home/airflow/.local/lib/python3.7/site-packages/psycopg2/extras.py", line 1270, in execute_values
    cur.execute(b''.join(parts))
psycopg2.errors.UndefinedTable: relation "flights" does not exist
LINE 1: INSERT INTO flights ("FL_DATE", "ORIGIN", "DEP_DELAY", pred,...
                    ^


The above exception was the direct cause of the following exception:

Traceback (most recent call last):
  File "/home/airflow/.local/lib/python3.7/site-packages/airflow/task/task_runner/standard_task_runner.py", line 85, in _start_by_fork
    args.func(args, dag=self.dag)
  File "/home/airflow/.local/lib/python3.7/site-packages/airflow/cli/cli_parser.py", line 48, in command
    return func(*args, **kwargs)
  File "/home/airflow/.local/lib/python3.7/site-packages/airflow/utils/cli.py", line 92, in wrapper
    return f(*args, **kwargs)
  File "/home/airflow/.local/lib/python3.7/site-packages/airflow/cli/commands/task_command.py", line 298, in task_run
    _run_task_by_selected_method(args, dag, ti)
  File "/home/airflow/.local/lib/python3.7/site-packages/airflow/cli/commands/task_command.py", line 107, in _run_task_by_selected_method
    _run_raw_task(args, ti)
  File "/home/airflow/.local/lib/python3.7/site-packages/airflow/cli/commands/task_command.py", line 184, in _run_raw_task
    error_file=args.error_file,
  File "/home/airflow/.local/lib/python3.7/site-packages/airflow/utils/session.py", line 70, in wrapper
    return func(*args, session=session, **kwargs)
  File "/home/airflow/.local/lib/python3.7/site-packages/airflow/models/taskinstance.py", line 1334, in _run_raw_task
    self._execute_task_with_callbacks(context)
  File "/home/airflow/.local/lib/python3.7/site-packages/airflow/models/taskinstance.py", line 1460, in _execute_task_with_callbacks
    result = self._execute_task(context, self.task)
  File "/home/airflow/.local/lib/python3.7/site-packages/airflow/models/taskinstance.py", line 1516, in _execute_task
    result = execute_callable(context=context)
  File "/home/airflow/.local/lib/python3.7/site-packages/airflow/operators/python.py", line 174, in execute
    return_value = self.execute_callable()
  File "/home/airflow/.local/lib/python3.7/site-packages/airflow/operators/python.py", line 188, in execute_callable
    return self.python_callable(*self.op_args, **self.op_kwargs)
  File "/opt/airflow/dags/dag_outliers.py", line 46, in read_process_write_file
    df1.to_sql(con=database_connection, name='flights', if_exists='replace',index=False)
  File "/home/airflow/.local/lib/python3.7/site-packages/pandas/core/generic.py", line 2882, in to_sql
    method=method,
  File "/home/airflow/.local/lib/python3.7/site-packages/pandas/io/sql.py", line 728, in to_sql
    **engine_kwargs,
  File "/home/airflow/.local/lib/python3.7/site-packages/pandas/io/sql.py", line 1770, in to_sql
    **engine_kwargs,
  File "/home/airflow/.local/lib/python3.7/site-packages/pandas/io/sql.py", line 1350, in insert_records
    raise err
  File "/home/airflow/.local/lib/python3.7/site-packages/pandas/io/sql.py", line 1340, in insert_records
    table.insert(chunksize=chunksize, method=method)
  File "/home/airflow/.local/lib/python3.7/site-packages/pandas/io/sql.py", line 967, in insert
    exec_insert(conn, keys, chunk_iter)
  File "/home/airflow/.local/lib/python3.7/site-packages/pandas/io/sql.py", line 882, in _execute_insert
    conn.execute(self.table.insert(), data)
  File "/home/airflow/.local/lib/python3.7/site-packages/sqlalchemy/engine/base.py", line 1289, in execute
    return meth(self, multiparams, params, _EMPTY_EXECUTION_OPTS)
  File "/home/airflow/.local/lib/python3.7/site-packages/sqlalchemy/sql/elements.py", line 326, in _execute_on_connection
    self, multiparams, params, execution_options
  File "/home/airflow/.local/lib/python3.7/site-packages/sqlalchemy/engine/base.py", line 1491, in _execute_clauseelement
    cache_hit=cache_hit,
  File "/home/airflow/.local/lib/python3.7/site-packages/sqlalchemy/engine/base.py", line 1846, in _execute_context
    e, statement, parameters, cursor, context
  File "/home/airflow/.local/lib/python3.7/site-packages/sqlalchemy/engine/base.py", line 2027, in _handle_dbapi_exception
    sqlalchemy_exception, with_traceback=exc_info[2], from_=e
  File "/home/airflow/.local/lib/python3.7/site-packages/sqlalchemy/util/compat.py", line 207, in raise_
    raise exception
  File "/home/airflow/.local/lib/python3.7/site-packages/sqlalchemy/engine/base.py", line 1783, in _execute_context
    cursor, statement, parameters, context
  File "/home/airflow/.local/lib/python3.7/site-packages/sqlalchemy/dialects/postgresql/psycopg2.py", line 957, in do_executemany
    **kwargs
  File "/home/airflow/.local/lib/python3.7/site-packages/psycopg2/extras.py", line 1270, in execute_values
    cur.execute(b''.join(parts))
sqlalchemy.exc.ProgrammingError: (psycopg2.errors.UndefinedTable) relation "flights" does not exist
LINE 1: INSERT INTO flights ("FL_DATE", "ORIGIN", "DEP_DELAY", pred,...
                    ^

[SQL: INSERT INTO flights ("FL_DATE", "ORIGIN", "DEP_DELAY", pred, result) VALUES (%(FL_DATE)s, %(ORIGIN)s, %(DEP_DELAY)s, %(pred)s, %(result)s)]
[parameters: ({'FL_DATE': '2009-01-01', 'ORIGIN': 'ABQ', 'DEP_DELAY': -8.0, 'pred': 0, 'result': 'normal'}, {'FL_DATE': '2009-01-01', 'ORIGIN': 'IAD', 'DEP_DELAY': -10.0, 'pred': 0, 'result': 'normal'}, {'FL_DATE': '2009-01-01', 'ORIGIN': 'IAH', 'DEP_DELAY': -0.23076923076923078, 'pred': 0, 'result': 'normal'}, {'FL_DATE': '2009-01-01', 'ORIGIN': 'IND', 'DEP_DELAY': -2.5, 'pred': 0, 'result': 'normal'}, {'FL_DATE': '2009-01-01', 'ORIGIN': 'JAN', 'DEP_DELAY': 3.0, 'pred': 1, 'result': 'outlier'}, {'FL_DATE': '2009-01-01', 'ORIGIN': 'JAX', 'DEP_DELAY': -9.0, 'pred': 0, 'result': 'normal'}, {'FL_DATE': '2009-01-01', 'ORIGIN': 'LFT', 'DEP_DELAY': -7.0, 'pred': 0, 'result': 'normal'}, {'FL_DATE': '2009-01-01', 'ORIGIN': 'GSO', 'DEP_DELAY': -1.0, 'pred': 0, 'result': 'normal'}  ... displaying 10 of 36 total bound parameter sets ...  {'FL_DATE': '2009-01-01', 'ORIGIN': 'RSW', 'DEP_DELAY': -9.0, 'pred': 0, 'result': 'normal'}, {'FL_DATE': '2009-01-01', 'ORIGIN': 'TYS', 'DEP_DELAY': -5.0, 'pred': 0, 'result': 'normal'})]
(Background on this error at: https://sqlalche.me/e/14/f405)
[2022-03-01 19:36:29,301] {local_task_job.py:154} INFO - Task exited with return code 1
[2022-03-01 19:36:29,320] {warnings.py:110} WARNING - /home/***/.local/lib/python3.7/site-packages/***/models/dag.py:1079: SADeprecationWarning: Query.value() is deprecated and will be removed in a future release.  Please use Query.with_entities() in combination with Query.scalar() (deprecated since: 1.4)
  return qry.value(DagModel.is_paused)

[2022-03-01 19:36:29,321] {warnings.py:110} WARNING - /home/***/.local/lib/python3.7/site-packages/***/models/dag.py:1079: SADeprecationWarning: Query.values() is deprecated and will be removed in a future release.  Please use Query.with_entities() (deprecated since: 1.4)
  return qry.value(DagModel.is_paused)

